Workbook

Sheet Instructions
B2: Market Stall Management System — Artisanal & Bulk Goods
B3: Catalog, supply chain, inventory and 2-year purchase/sell-through analysis
B6: About this portfolio project
B7: This workbook is a portfolio piece. The original project was built in Spanish for a real family market-stall ("feria") business; this English version is a full adaptation and translation of that work.
B8: IMPORTANT — all supplier names, contact details and locations are FICTITIOUS, and all monetary amounts are APPROXIMATE. Prices are grounded in real reference ranges from Chilean fairs and wholesale suppliers (2025-2026), but they are illustrative, not actual quotes. Town/region names are real (to keep the geography plausible) but the businesses located there are invented.
B9: Currency: amounts are shown in both CLP (Chilean peso) and USD. Conversion uses 1 USD = 935 CLP (observed rate, 21 Jul 2026). Consumer sale prices are rounded to whole or half units (in CLP, to the nearest 500) to match how prices are actually quoted at a stall.
B11: How the workbook is organized
B12: 1. Products
B13: Master catalog (128 products): sale price in CLP and USD, unit, whether the price is by weight (kg) or by unit/package, current stock (High/Medium/Low), essential flag, peak season, and the auto-filled cost & margin pulled from the primary supplier.
B14: 2. Suppliers
B15: The 22 suppliers, each with contact details and whether they deliver or you must pick up.
B16: 3. Supply_Links
... B44: Green / Yellow / Red on Stock = High / Medium / Low.

Sheet Dashboard
B1: Dashboard — Market Stall
B2: Synthetic purchase cohorts Jul 2023–Jun 2025. Outcomes include future batch closures.
B4: Total Products | E4: Essential Products | H4: Cohort gross margin
B5: =COUNTA(TblProducts[ID]) -> 128 | E5: =COUNTIF(TblProducts[Essential],"Yes") -> 15 | H5: =SUM(TblOutcomes[Gross Profit (CLP)])/SUM(TblOutcomes[Revenue (CLP)]) -> 0.25033531
B8: Cohort revenue (CLP) | E8: Cohort gross profit (CLP) | H8: Waste cost / purchase cost
B9: =SUM(TblOutcomes[Revenue (CLP)]) -> 412926945 | E9: =SUM(TblOutcomes[Gross Profit (CLP)]) -> 103370195 | H9: =IF(COUNT(TblOutcomes[Waste Cost (CLP)])<>COUNTA(TblOutcomes[BatchID]),"n.a.",SUM(TblOutcomes[Waste Cost (CLP)])/SUM(TblPurchases[Batch Cost (CLP)])) -> 0.029048528
B12: # Suppliers | E12: Urgent Stock Alerts | H12: Batches (2 years)
B13: =COUNTA(TblSuppliers[ID]) -> 22 | E13: =COUNTIF(Restock_Alerts!H5:H132,"URGENT") -> 2 | H13: =COUNTA(TblOutcomes[BatchID]) -> 3825
B17: Purchase-cohort outcomes (USD illustrative FX; waste cost %)
B18: Month | C18: Revenue (USD) | D18: Waste cost %
B19: 2023-07 | C19: 19975 | D19: =SUMIFS(TblOutcomes[Waste Cost (CLP)],TblOutcomes[Purchase Date],">="&DATE(VALUE(LEFT(B19,4)),VALUE(RIGHT(B19,2)),1),TblOutcomes[Purchase Date],"<"&EDATE(DATE(VALUE(LEFT(B19,4)),VALUE(RIGHT(B19,2)),1),1))/SUMIFS(TblPurchases[Batch Cost (CLP)],TblPurchases[Purchase Date],">="&DATE(VALUE(LEFT(B19,4)),VALUE(RIGHT(B19,2)),1),TblPurchases[Purchase Date],"<"&EDATE(DATE(VALUE(LEFT(B19,4)),VALUE(RIGHT(B19,2)),1),1))*100 -> 2.3249655
B20: 2023-08 | C20: 19974 | D20: =SUMIFS(TblOutcomes[Waste Cost (CLP)],TblOutcomes[Purchase Date],">="&DATE(VALUE(LEFT(B20,4)),VALUE(RIGHT(B20,2)),1),TblOutcomes[Purchase Date],"<"&EDATE(DATE(VALUE(LEFT(B20,4)),VALUE(RIGHT(B20,2)),1),1))/SUMIFS(TblPurchases[Batch Cost (CLP)],TblPurchases[Purchase Date],">="&DATE(VALUE(LEFT(B20,4)),VALUE(RIGHT(B20,2)),1),TblPurchases[Purchase Date],"<"&EDATE(DATE(VALUE(LEFT(B20,4)),VALUE(RIGHT(B20,2)),1),1))*100 -> 2.2608265
B21: 2023-09 | C21: 22866 | D21: =SUMIFS(TblOutcomes[Waste Cost (CLP)],TblOutcomes[Purchase Date],">="&DATE(VALUE(LEFT(B21,4)),VALUE(RIGHT(B21,2)),1),TblOutcomes[Purchase Date],"<"&EDATE(DATE(VALUE(LEFT(B21,4)),VALUE(RIGHT(B21,2)),1),1))/SUMIFS(TblPurchases[Batch Cost (CLP)],TblPurchases[Purchase Date],">="&DATE(VALUE(LEFT(B21,4)),VALUE(RIGHT(B21,2)),1),TblPurchases[Purchase Date],"<"&EDATE(DATE(VALUE(LEFT(B21,4)),VALUE(RIGHT(B21,2)),1),1))*100 -> 1.769779
B22: 2023-10 | C22: 16117 | D22: =SUMIFS(TblOutcomes[Waste Cost (CLP)],TblOutcomes[Purchase Date],">="&DATE(VALUE(LEFT(B22,4)),VALUE(RIGHT(B22,2)),1),TblOutcomes[Purchase Date],"<"&EDATE(DATE(VALUE(LEFT(B22,4)),VALUE(RIGHT(B22,2)),1),1))/SUMIFS(TblPurchases[Batch Cost (CLP)],TblPurchases[Purchase Date],">="&DATE(VALUE(LEFT(B22,4)),VALUE(RIGHT(B22,2)),1),TblPurchases[Purchase Date],"<"&EDATE(DATE(VALUE(LEFT(B22,4)),VALUE(RIGHT(B22,2)),1),1))*100 -> 3.3572784
B23: 2023-11 | C23: 15155 | D23: =SUMIFS(TblOutcomes[Waste Cost (CLP)],TblOutcomes[Purchase Date],">="&DATE(VALUE(LEFT(B23,4)),VALUE(RIGHT(B23,2)),1),TblOutcomes[Purchase Date],"<"&EDATE(DATE(VALUE(LEFT(B23,4)),VALUE(RIGHT(B23,2)),1),1))/SUMIFS(TblPurchases[Batch Cost (CLP)],TblPurchases[Purchase Date],">="&DATE(VALUE(LEFT(B23,4)),VALUE(RIGHT(B23,2)),1),TblPurchases[Purchase Date],"<"&EDATE(DATE(VALUE(LEFT(B23,4)),VALUE(RIGHT(B23,2)),1),1))*100 -> 3.672648
B24: 2023-12 | C24: 18974 | D24: =SUMIFS(TblOutcomes[Waste Cost (CLP)],TblOutcomes[Purchase Date],">="&DATE(VALUE(LEFT(B24,4)),VALUE(RIGHT(B24,2)),1),TblOutcomes[Purchase Date],"<"&EDATE(DATE(VALUE(LEFT(B24,4)),VALUE(RIGHT(B24,2)),1),1))/SUMIFS(TblPurchases[Batch Cost (CLP)],TblPurchases[Purchase Date],">="&DATE(VALUE(LEFT(B24,4)),VALUE(RIGHT(B24,2)),1),TblPurchases[Purchase Date],"<"&EDATE(DATE(VALUE(LEFT(B24,4)),VALUE(RIGHT(B24,2)),1),1))*100 -> 2.4653392
B25: 2024-01 | C25: 15545 | D25: =SUMIFS(TblOutcomes[Waste Cost (CLP)],TblOutcomes[Purchase Date],">="&DATE(VALUE(LEFT(B25,4)),VALUE(RIGHT(B25,2)),1),TblOutcomes[Purchase Date],"<"&EDATE(DATE(VALUE(LEFT(B25,4)),VALUE(RIGHT(B25,2)),1),1))/SUMIFS(TblPurchases[Batch Cost (CLP)],TblPurchases[Purchase Date],">="&DATE(VALUE(LEFT(B25,4)),VALUE(RIGHT(B25,2)),1),TblPurchases[Purchase Date],"<"&EDATE(DATE(VALUE(LEFT(B25,4)),VALUE(RIGHT(B25,2)),1),1))*100 -> 4.714208
B26: 2024-02 | C26: 14415 | D26: =SUMIFS(TblOutcomes[Waste Cost (CLP)],TblOutcomes[Purchase Date],">="&DATE(VALUE(LEFT(B26,4)),VALUE(RIGHT(B26,2)),1),TblOutcomes[Purchase Date],"<"&EDATE(DATE(VALUE(LEFT(B26,4)),VALUE(RIGHT(B26,2)),1),1))/SUMIFS(TblPurchases[Batch Cost (CLP)],TblPurchases[Purchase Date],">="&DATE(VALUE(LEFT(B26,4)),VALUE(RIGHT(B26,2)),1),TblPurchases[Purchase Date],"<"&EDATE(DATE(VALUE(LEFT(B26,4)),VALUE(RIGHT(B26,2)),1),1))*100 -> 6.2422039
B27: 2024-03 | C27: 15262 | D27: =SUMIFS(TblOutcomes[Waste Cost (CLP)],TblOutcomes[Purchase Date],">="&DATE(VALUE(LEFT(B27,4)),VALUE(RIGHT(B27,2)),1),TblOutcomes[Purchase Date],"<"&EDATE(DATE(VALUE(LEFT(B27,4)),VALUE(RIGHT(B27,2)),1),1))/SUMIFS(TblPurchases[Batch Cost (CLP)],TblPurchases[Purchase Date],">="&DATE(VALUE(LEFT(B27,4)),VALUE(RIGHT(B27,2)),1),TblPurchases[Purchase Date],"<"&EDATE(DATE(VALUE(LEFT(B27,4)),VALUE(RIGHT(B27,2)),1),1))*100 -> 3.3497308
B28: 2024-04 | C28: 19516 | D28: =SUMIFS(TblOutcomes[Waste Cost (CLP)],TblOutcomes[Purchase Date],">="&DATE(VALUE(LEFT(B28,4)),VALUE(RIGHT(B28,2)),1),TblOutcomes[Purchase Date],"<"&EDATE(DATE(VALUE(LEFT(B28,4)),VALUE(RIGHT(B28,2)),1),1))/SUMIFS(TblPurchases[Batch Cost (CLP)],TblPurchases[Purchase Date],">="&DATE(VALUE(LEFT(B28,4)),VALUE(RIGHT(B28,2)),1),TblPurchases[Purchase Date],"<"&EDATE(DATE(VALUE(LEFT(B28,4)),VALUE(RIGHT(B28,2)),1),1))*100 -> 2.3999825
B29: 2024-05 | C29: 21114 | D29: =SUMIFS(TblOutcomes[Waste Cost (CLP)],TblOutcomes[Purchase Date],">="&DATE(VALUE(LEFT(B29,4)),VALUE(RIGHT(B29,2)),1),TblOutcomes[Purchase Date],"<"&EDATE(DATE(VALUE(LEFT(B29,4)),VALUE(RIGHT(B29,2)),1),1))/SUMIFS(TblPurchases[Batch Cost (CLP)],TblPurchases[Purchase Date],">="&DATE(VALUE(LEFT(B29,4)),VALUE(RIGHT(B29,2)),1),TblPurchases[Purchase Date],"<"&EDATE(DATE(VALUE(LEFT(B29,4)),VALUE(RIGHT(B29,2)),1),1))*100 -> 2.4376556
B30: 2024-06 | C30: 20107 | D30: =SUMIFS(TblOutcomes[Waste Cost (CLP)],TblOutcomes[Purchase Date],">="&DATE(VALUE(LEFT(B30,4)),VALUE(RIGHT(B30,2)),1),TblOutcomes[Purchase Date],"<"&EDATE(DATE(VALUE(LEFT(B30,4)),VALUE(RIGHT(B30,2)),1),1))/SUMIFS(TblPurchases[Batch Cost (CLP)],TblPurchases[Purchase Date],">="&DATE(VALUE(LEFT(B30,4)),VALUE(RIGHT(B30,2)),1),TblPurchases[Purchase Date],"<"&EDATE(DATE(VALUE(LEFT(B30,4)),VALUE(RIGHT(B30,2)),1),1))*100 -> 2.830839
... B42: 2025-06 | C42: 20324 | D42: =SUMIFS(TblOutcomes[Waste Cost (CLP)],TblOutcomes[Purchase Date],">="&DATE(VALUE(LEFT(B42,4)),VALUE(RIGHT(B42,2)),1),TblOutcomes[Purchase Date],"<"&EDATE(DATE(VALUE(LEFT(B42,4)),VALUE(RIGHT(B42,2)),1),1))/SUMIFS(TblPurchases[Batch Cost (CLP)],TblPurchases[Purchase Date],">="&DATE(VALUE(LEFT(B42,4)),VALUE(RIGHT(B42,2)),1),TblPurchases[Purchase Date],"<"&EDATE(DATE(VALUE(LEFT(B42,4)),VALUE(RIGHT(B42,2)),1),1))*100 -> 1.9721153
B45: Quick Lookup — by Category
B46: Pick a category: | D46: Candy
B48: # Products | C48: # Essential | D48: Avg Price (CLP) | E48: Avg Margin % | F48: 2Y Revenue (CLP) | G48: 2Y Waste % | H48: Stk High | I48: Stk Med | J48: Stk Low
B49: =INDEX(Category_Summary!$C$5:$C$18,MATCH(D46,Category_Summary!$B$5:$B$18,0)) -> 17 | C49: =INDEX(Category_Summary!$D$5:$D$18,MATCH(D46,Category_Summary!$B$5:$B$18,0)) -> 0 | D49: =INDEX(Category_Summary!$E$5:$E$18,MATCH(D46,Category_Summary!$B$5:$B$18,0)) -> 1088.2353 | E49: =INDEX(Category_Summary!$F$5:$F$18,MATCH(D46,Category_Summary!$B$5:$B$18,0)) -> 0.31323529 | F49: =INDEX(Category_Summary!$G$5:$G$18,MATCH(D46,Category_Summary!$B$5:$B$18,0)) -> 15758630 | G49: =INDEX(Category_Summary!$H$5:$H$18,MATCH(D46,Category_Summary!$B$5:$B$18,0)) -> 0.014816193 | H49: =INDEX(Category_Summary!$I$5:$I$18,MATCH(D46,Category_Summary!$B$5:$B$18,0)) -> 8 | I49: =INDEX(Category_Summary!$J$5:$J$18,MATCH(D46,Category_Summary!$B$5:$B$18,0)) -> 7 | J49: =INDEX(Category_Summary!$K$5:$K$18,MATCH(D46,Category_Summary!$B$5:$B$18,0)) -> 2
B52: Quick Lookup — by Season
B53: Pick a season: | D53: Spring-Summer
B55: # Products | C55: # Essential | D55: % of Catalog | E55: Avg Price (CLP) | F55: Avg Margin % | G55: Stk High | H55: Stk Med | I55: Stk Low
B56: =INDEX(Season_Demand!$C$5:$C$7,MATCH(D53,Season_Demand!$B$5:$B$7,0)) -> 13 | C56: =INDEX(Season_Demand!$D$5:$D$7,MATCH(D53,Season_Demand!$B$5:$B$7,0)) -> 5 | D56: =INDEX(Season_Demand!$E$5:$E$7,MATCH(D53,Season_Demand!$B$5:$B$7,0)) -> 0.1015625 | E56: =INDEX(Season_Demand!$F$5:$F$7,MATCH(D53,Season_Demand!$B$5:$B$7,0)) -> 2807.6923 | F56: =INDEX(Season_Demand!$G$5:$G$7,MATCH(D53,Season_Demand!$B$5:$B$7,0)) -> 0.28011905 | G56: =INDEX(Season_Demand!$H$5:$H$7,MATCH(D53,Season_Demand!$B$5:$B$7,0)) -> 5 | H56: =INDEX(Season_Demand!$I$5:$I$7,MATCH(D53,Season_Demand!$B$5:$B$7,0)) -> 4 | I56: =INDEX(Season_Demand!$J$5:$J$7,MATCH(D53,Season_Demand!$B$5:$B$7,0)) -> 4

Sheet Supply_Dashboard
B1: Supply Chain Dashboard
B2: Supplier comparison, dependency risk and a quick supplier lookup card
B4: # Suppliers | E4: % Links w/ Delivery | H4: Avg Lead Time (days)
B5: =COUNTA(TblSuppliers[ID]) -> 22 | E5: =COUNTIF(TblSupply[Delivery?],"Yes")/COUNTA(TblSupply[ID]) -> 0.6640625 | H5: =AVERAGE(TblSupply[Lead Time (days)]) -> 3.2851562
B8: Backup Coverage | E8: High-Dependency Suppliers | H8: Fastest Supplier
B9: =COUNTIF(TblSupply[SupplierRole],"Backup")/COUNTA(TblProducts[ID]) -> 1 | E9: =COUNTIF(Supplier_Scorecard!H5:H14,"High") -> 2 | H9: =INDEX(Supplier_Scorecard!$B$5:$B$14,MATCH(MIN(Supplier_Scorecard!$D$5:$D$14),Supplier_Scorecard!$D$5:$D$14,0)) -> Doña Rosa Pickles
B13: Supplier Lookup — contact card
B14: Pick a supplier: | D14: El Olivar Olives Ltd.
B16: Address | D16: =IFERROR(INDEX(TblSuppliers[Address],MATCH(D14,TblSuppliers[Supplier],0)),"") -> 450 San Pedro Rd, Melipilla
B17: Phone | D17: =IFERROR(INDEX(TblSuppliers[Phone],MATCH(D14,TblSuppliers[Supplier],0)),"") -> +56 9 5511 2233
B18: Email | D18: =IFERROR(INDEX(TblSuppliers[Email],MATCH(D14,TblSuppliers[Supplier],0)),"") -> orders@elolivar.example
B19: Delivery? | D19: =IFERROR(INDEX(TblSuppliers[Delivery?],MATCH(D14,TblSuppliers[Supplier],0)),"") -> Yes
B20: # Products supplied (any role) | D20: =COUNTIFS(TblSupply[Supplier],D14) -> 11
B21: # as Primary | D21: =COUNTIFS(TblSupply[Supplier],D14,TblSupply[SupplierRole],"Primary") -> 11
B22: # as Backup | D22: =COUNTIFS(TblSupply[Supplier],D14,TblSupply[SupplierRole],"Backup") -> 0
B23: Avg Lead Time (days) | D23: =IFERROR(AVERAGEIFS(TblSupply[Lead Time (days)],TblSupply[Supplier],D14),"") -> 2.1818182
B47: Mode | C47: # Links
B48: Delivery | C48: =COUNTIF(TblSupply[Delivery?],"Yes") -> 170
B49: Pickup | C49: =COUNTIF(TblSupply[Delivery?],"No") -> 86

Sheet Products
B1: Product Catalog
B3: ID | C3: Product | D3: Category | E3: Sale Unit | F3: Price Type | G3: Essential | H3: Peak Season | I3: Current Stock | J3: Sale Price (CLP) | K3: Sale Price (USD) | L3: Cost (CLP) | M3: Margin (CLP) | N3: Margin (%)
B4: P001 | C4: Olives 120/140 (extra large), brined | D4: Olives | E4: kg | F4: By Weight (kg) | G4: Yes | H4: Spring-Summer | I4: High | J4: 4000 | K4: 4.28 | L4: =IFERROR(SUMIFS(TblSupply[PurchasePrice_CLP],TblSupply[ProductID],B4,TblSupply[SupplierRole],"Primary"),"") -> 2950 | M4: =IF(L4="","",J4-L4) -> 1050 | N4: =IF(L4="","",M4/J4) -> 0.2625
B5: P002 | C5: Olives 140/160 (large), brined | D5: Olives | E5: kg | F5: By Weight (kg) | G5: Yes | H5: Spring-Summer | I5: Low | J5: 3500 | K5: 3.74 | L5: =IFERROR(SUMIFS(TblSupply[PurchasePrice_CLP],TblSupply[ProductID],B5,TblSupply[SupplierRole],"Primary"),"") -> 2500 | M5: =IF(L5="","",J5-L5) -> 1000 | N5: =IF(L5="","",M5/J5) -> 0.28571429
B6: P003 | C6: Olives 160/180, brined | D6: Olives | E6: kg | F6: By Weight (kg) | G6: Yes | H6: Spring-Summer | I6: Medium | J6: 3500 | K6: 3.74 | L6: =IFERROR(SUMIFS(TblSupply[PurchasePrice_CLP],TblSupply[ProductID],B6,TblSupply[SupplierRole],"Primary"),"") -> 2450 | M6: =IF(L6="","",J6-L6) -> 1050 | N6: =IF(L6="","",M6/J6) -> 0.3
B7: P004 | C7: Olives 180/200, brined | D7: Olives | E7: kg | F7: By Weight (kg) | G7: No | H7: Spring-Summer | I7: Medium | J7: 3000 | K7: 3.21 | L7: =IFERROR(SUMIFS(TblSupply[PurchasePrice_CLP],TblSupply[ProductID],B7,TblSupply[SupplierRole],"Primary"),"") -> 2050 | M7: =IF(L7="","",J7-L7) -> 950 | N7: =IF(L7="","",M7/J7) -> 0.31666667
B8: P005 | C8: Olives 200/220, brined | D8: Olives | E8: kg | F8: By Weight (kg) | G8: Yes | H8: Spring-Summer | I8: High | J8: 3000 | K8: 3.21 | L8: =IFERROR(SUMIFS(TblSupply[PurchasePrice_CLP],TblSupply[ProductID],B8,TblSupply[SupplierRole],"Primary"),"") -> 2100 | M8: =IF(L8="","",J8-L8) -> 900 | N8: =IF(L8="","",M8/J8) -> 0.3
B9: P006 | C9: Olives 220/240, brined | D9: Olives | E9: kg | F9: By Weight (kg) | G9: No | H9: Spring-Summer | I9: High | J9: 3000 | K9: 3.21 | L9: =IFERROR(SUMIFS(TblSupply[PurchasePrice_CLP],TblSupply[ProductID],B9,TblSupply[SupplierRole],"Primary"),"") -> 2200 | M9: =IF(L9="","",J9-L9) -> 800 | N9: =IF(L9="","",M9/J9) -> 0.26666667
B10: P007 | C10: Olives 240/260 (small), brined | D10: Olives | E10: kg | F10: By Weight (kg) | G10: No | H10: Spring-Summer | I10: High | J10: 2500 | K10: 2.67 | L10: =IFERROR(SUMIFS(TblSupply[PurchasePrice_CLP],TblSupply[ProductID],B10,TblSupply[SupplierRole],"Primary"),"") -> 1850 | M10: =IF(L10="","",J10-L10) -> 650 | N10: =IF(L10="","",M10/J10) -> 0.26
B11: P008 | C11: Pitted olives | D11: Olives | E11: kg | F11: By Weight (kg) | G11: No | H11: Spring-Summer | I11: Low | J11: 3500 | K11: 3.74 | L11: =IFERROR(SUMIFS(TblSupply[PurchasePrice_CLP],TblSupply[ProductID],B11,TblSupply[SupplierRole],"Primary"),"") -> 2450 | M11: =IF(L11="","",J11-L11) -> 1050 | N11: =IF(L11="","",M11/J11) -> 0.3
B12: P009 | C12: Sliced olives (for salads) | D12: Olives | E12: kg | F12: By Weight (kg) | G12: No | H12: Spring-Summer | I12: Medium | J12: 3000 | K12: 3.21 | L12: =IFERROR(SUMIFS(TblSupply[PurchasePrice_CLP],TblSupply[ProductID],B12,TblSupply[SupplierRole],"Primary"),"") -> 2150 | M12: =IF(L12="","",J12-L12) -> 850 | N12: =IF(L12="","",M12/J12) -> 0.28333333
B13: P010 | C13: Cracked green olives with garlic | D13: Olives | E13: kg | F13: By Weight (kg) | G13: No | H13: Spring-Summer | I13: Medium | J13: 3000 | K13: 3.21 | L13: =IFERROR(SUMIFS(TblSupply[PurchasePrice_CLP],TblSupply[ProductID],B13,TblSupply[SupplierRole],"Primary"),"") -> 2100 | M13: =IF(L13="","",J13-L13) -> 900 | N13: =IF(L13="","",M13/J13) -> 0.3
B14: P011 | C14: Black olive pate, jar 250g | D14: Olives | E14: jar 250g | F14: By Unit/Package | G14: No | H14: All year | I14: High | J14: 3500 | K14: 3.74 | L14: =IFERROR(SUMIFS(TblSupply[PurchasePrice_CLP],TblSupply[ProductID],B14,TblSupply[SupplierRole],"Primary"),"") -> 2500 | M14: =IF(L14="","",J14-L14) -> 1000 | N14: =IF(L14="","",M14/J14) -> 0.28571429
B15: P012 | C15: Cooked mote (hominy wheat) | D15: Grains | E15: kg | F15: By Weight (kg) | G15: Yes | H15: Spring-Summer | I15: Low | J15: 1500 | K15: 1.6 | L15: =IFERROR(SUMIFS(TblSupply[PurchasePrice_CLP],TblSupply[ProductID],B15,TblSupply[SupplierRole],"Primary"),"") -> 1150 | M15: =IF(L15="","",J15-L15) -> 350 | N15: =IF(L15="","",M15/J15) -> 0.23333333
... B131: P128 | C131: Vacuum bag 20x30cm (pack of 50) | D131: Packaging | E131: pack 50 | F131: By Unit/Package | G131: No | H131: All year | I131: Low | J131: 4500 | K131: 4.81 | L131: =IFERROR(SUMIFS(TblSupply[PurchasePrice_CLP],TblSupply[ProductID],B131,TblSupply[SupplierRole],"Primary"),"") -> 3050 | M131: =IF(L131="","",J131-L131) -> 1450 | N131: =IF(L131="","",M131/J131) -> 0.32222222

Sheet Suppliers
B1: Suppliers
B3: ID | C3: Supplier | D3: Address | E3: Phone | F3: Email | G3: Delivery? | H3: Pickup?
B4: S001 | C4: El Olivar Olives Ltd. | D4: 450 San Pedro Rd, Melipilla | E4: +56 9 5511 2233 | F4: orders@elolivar.example | G4: Yes | H4: No
B5: S002 | C5: Aceitunera Central SpA | D5: 1220 Longitudinal Hwy, San Fernando | E5: +56 9 5610 8842 | F5: ventas@aceituneracentral.example | G5: No | H5: Yes
B6: S003 | C6: San Vicente Grains & Legumes | D6: 780 Freire Ave, San Vicente | E6: +56 9 4422 1188 | F6: sales@svgrains.example | G6: No | H6: Yes
B7: S004 | C7: Molino del Valle | D7: 95 Estacion St, Rengo | E7: +56 9 4470 3319 | F7: contacto@molinodelvalle.example | G7: Yes | H7: No
B8: S005 | C8: Doña Rosa Pickles | D8: 233 Los Aromos, Rancagua | E8: +56 9 6633 9944 | F8: donarosa.pickles@example | G8: Yes | H8: No
B9: S006 | C9: Conservas El Huerto | D9: 410 Membrillar, Rancagua | E9: +56 9 6690 2255 | F9: elhuerto.conservas@example | G9: No | H9: Yes
B10: S007 | C10: Curico Chili & Sauces | D10: Km 178 Route 5 South, Curico | E10: +56 9 7788 1122 | F10: chili@curicosauces.example | G10: No | H10: Yes
B11: S008 | C11: Merken del Sur | D11: 67 Caupolican, Temuco | E11: +56 9 7810 4471 | F11: ventas@merkendelsur.example | G11: Yes | H11: No
B12: S009 | C12: Valley Spices SpA | D12: 1560 Balmaceda Ave, Rancagua | E12: +56 9 3344 5566 | F12: orders@valleyspices.example | G12: Yes | H12: No
B13: S010 | C13: Especias Andinas | D13: 330 Independencia, Santiago | E13: +56 9 3380 1190 | F13: andinas.especias@example | G13: Yes | H13: No
B14: S011 | C14: Los Ulmos Apiary | D14: Santa Elena Farm, Pichidegua | E14: +56 9 8899 0011 | F14: apiary@losulmos.example | G14: No | H14: Yes
... B25: S022 | C25: Envases del Pacifico | D25: 88 Portales, Valparaiso | E25: +56 9 3060 2214 | F25: ventas@envasespacifico.example | G25: Yes | H25: No

Sheet Supply_Links
B1: Supply Links — Primary & Backup suppliers per product
B2: Every product has a documented fallback supplier in case the primary one fails.
B4: ID | C4: ProductID | D4: Product | E4: Category | F4: SupplierRole | G4: SupplierID | H4: Supplier | I4: PurchasePrice_CLP | J4: Purchase (USD) | K4: Price Type | L4: Unit | M4: Lead Time (days) | N4: Delivery?
B5: SUP0001 | C5: P001 | D5: Olives 120/140 (extra large), brined | E5: Olives | F5: Primary | G5: S001 | H5: El Olivar Olives Ltd. | I5: 2950 | J5: 3.16 | K5: By Weight (kg) | L5: kg | M5: 3 | N5: Yes
B6: SUP0002 | C6: P001 | D6: Olives 120/140 (extra large), brined | E6: Olives | F6: Backup | G6: S002 | H6: Aceitunera Central SpA | I6: 3000 | J6: 3.21 | K6: By Weight (kg) | L6: kg | M6: 10 | N6: No
B7: SUP0003 | C7: P002 | D7: Olives 140/160 (large), brined | E7: Olives | F7: Primary | G7: S001 | H7: El Olivar Olives Ltd. | I7: 2500 | J7: 2.67 | K7: By Weight (kg) | L7: kg | M7: 2 | N7: Yes
B8: SUP0004 | C8: P002 | D8: Olives 140/160 (large), brined | E8: Olives | F8: Backup | G8: S002 | H8: Aceitunera Central SpA | I8: 2700 | J8: 2.89 | K8: By Weight (kg) | L8: kg | M8: 5 | N8: No
B9: SUP0005 | C9: P003 | D9: Olives 160/180, brined | E9: Olives | F9: Primary | G9: S001 | H9: El Olivar Olives Ltd. | I9: 2450 | J9: 2.62 | K9: By Weight (kg) | L9: kg | M9: 3 | N9: Yes
B10: SUP0006 | C10: P003 | D10: Olives 160/180, brined | E10: Olives | F10: Backup | G10: S002 | H10: Aceitunera Central SpA | I10: 2600 | J10: 2.78 | K10: By Weight (kg) | L10: kg | M10: 3 | N10: No
B11: SUP0007 | C11: P004 | D11: Olives 180/200, brined | E11: Olives | F11: Primary | G11: S001 | H11: El Olivar Olives Ltd. | I11: 2050 | J11: 2.19 | K11: By Weight (kg) | L11: kg | M11: 1 | N11: Yes
B12: SUP0008 | C12: P004 | D12: Olives 180/200, brined | E12: Olives | F12: Backup | G12: S002 | H12: Aceitunera Central SpA | I12: 2300 | J12: 2.46 | K12: By Weight (kg) | L12: kg | M12: 2 | N12: No
B13: SUP0009 | C13: P005 | D13: Olives 200/220, brined | E13: Olives | F13: Primary | G13: S001 | H13: El Olivar Olives Ltd. | I13: 2100 | J13: 2.25 | K13: By Weight (kg) | L13: kg | M13: 5 | N13: Yes
B14: SUP0010 | C14: P005 | D14: Olives 200/220, brined | E14: Olives | F14: Backup | G14: S002 | H14: Aceitunera Central SpA | I14: 2300 | J14: 2.46 | K14: By Weight (kg) | L14: kg | M14: 10 | N14: No
B15: SUP0011 | C15: P006 | D15: Olives 220/240, brined | E15: Olives | F15: Primary | G15: S001 | H15: El Olivar Olives Ltd. | I15: 2200 | J15: 2.35 | K15: By Weight (kg) | L15: kg | M15: 2 | N15: Yes
B16: SUP0012 | C16: P006 | D16: Olives 220/240, brined | E16: Olives | F16: Backup | G16: S002 | H16: Aceitunera Central SpA | I16: 2200 | J16: 2.35 | K16: By Weight (kg) | L16: kg | M16: 5 | N16: No
... B260: SUP0256 | C260: P128 | D260: Vacuum bag 20x30cm (pack of 50) | E260: Packaging | F260: Backup | G260: S022 | H260: Envases del Pacifico | I260: 3200 | J260: 3.42 | K260: By Unit/Package | L260: pack 50 | M260: 2 | N260: Yes

Sheet Purchases
B1: Purchases — 2 years of supply batches (Jul 2023 - Jun 2025)
B2: One row = one batch bought from a supplier, with quantity, purchase date and expiry date.
B4: BatchID | C4: ProductID | D4: Product | E4: Category | F4: Role | G4: SupplierID | H4: Supplier | I4: Purchase Date | J4: Qty | K4: Unit | L4: Unit Cost (CLP) | M4: Batch Cost (CLP) | N4: Batch Cost (USD) | O4: Expiry Date | P4: Expiry Type | Q4: Season
B5: B00001 | C5: P001 | D5: Olives 120/140 (extra large), brined | E5: Olives | F5: Primary | G5: S001 | H5: El Olivar Olives Ltd. | I5: 45116 | J5: 16 | K5: kg | L5: 2950 | M5: 47200 | N5: 50.48 | O5: 45161 | P5: Estimated | Q5: Winter
B6: B00002 | C6: P001 | D6: Olives 120/140 (extra large), brined | E6: Olives | F6: Primary | G6: S001 | H6: El Olivar Olives Ltd. | I6: 45127 | J6: 13 | K6: kg | L6: 2950 | M6: 38350 | N6: 41.02 | O6: 45172 | P6: Estimated | Q6: Winter
B7: B00003 | C7: P001 | D7: Olives 120/140 (extra large), brined | E7: Olives | F7: Primary | G7: S001 | H7: El Olivar Olives Ltd. | I7: 45136 | J7: 13 | K7: kg | L7: 2950 | M7: 38350 | N7: 41.02 | O7: 45181 | P7: Estimated | Q7: Winter
B8: B00004 | C8: P001 | D8: Olives 120/140 (extra large), brined | E8: Olives | F8: Primary | G8: S001 | H8: El Olivar Olives Ltd. | I8: 45143 | J8: 16 | K8: kg | L8: 2950 | M8: 47200 | N8: 50.48 | O8: 45188 | P8: Estimated | Q8: Winter
B9: B00005 | C9: P001 | D9: Olives 120/140 (extra large), brined | E9: Olives | F9: Primary | G9: S001 | H9: El Olivar Olives Ltd. | I9: 45151 | J9: 15 | K9: kg | L9: 2950 | M9: 44250 | N9: 47.33 | O9: 45196 | P9: Estimated | Q9: Winter
B10: B00006 | C10: P001 | D10: Olives 120/140 (extra large), brined | E10: Olives | F10: Primary | G10: S001 | H10: El Olivar Olives Ltd. | I10: 45159 | J10: 16 | K10: kg | L10: 2950 | M10: 47200 | N10: 50.48 | O10: 45204 | P10: Estimated | Q10: Winter
B11: B00007 | C11: P001 | D11: Olives 120/140 (extra large), brined | E11: Olives | F11: Primary | G11: S001 | H11: El Olivar Olives Ltd. | I11: 45166 | J11: 17 | K11: kg | L11: 2950 | M11: 50150 | N11: 53.64 | O11: 45211 | P11: Estimated | Q11: Winter
B12: B00008 | C12: P001 | D12: Olives 120/140 (extra large), brined | E12: Olives | F12: Backup | G12: S002 | H12: Aceitunera Central SpA | I12: 45175 | J12: 19 | K12: kg | L12: 3000 | M12: 57000 | N12: 60.96 | O12: 45220 | P12: Estimated | Q12: Spring
B13: B00009 | C13: P001 | D13: Olives 120/140 (extra large), brined | E13: Olives | F13: Primary | G13: S001 | H13: El Olivar Olives Ltd. | I13: 45185 | J13: 18 | K13: kg | L13: 2950 | M13: 53100 | N13: 56.79 | O13: 45230 | P13: Estimated | Q13: Spring
B14: B00010 | C14: P001 | D14: Olives 120/140 (extra large), brined | E14: Olives | F14: Primary | G14: S001 | H14: El Olivar Olives Ltd. | I14: 45194 | J14: 20 | K14: kg | L14: 2950 | M14: 59000 | N14: 63.1 | O14: 45239 | P14: Estimated | Q14: Spring
B15: B00011 | C15: P001 | D15: Olives 120/140 (extra large), brined | E15: Olives | F15: Primary | G15: S001 | H15: El Olivar Olives Ltd. | I15: 45203 | J15: 35 | K15: kg | L15: 2950 | M15: 103250 | N15: 110.43 | O15: 45248 | P15: Estimated | Q15: Spring
B16: B00012 | C16: P001 | D16: Olives 120/140 (extra large), brined | E16: Olives | F16: Primary | G16: S001 | H16: El Olivar Olives Ltd. | I16: 45211 | J16: 34 | K16: kg | L16: 2950 | M16: 100300 | N16: 107.27 | O16: 45256 | P16: Estimated | Q16: Spring
... B3829: B03825 | C3829: P128 | D3829: Vacuum bag 20x30cm (pack of 50) | E3829: Packaging | F3829: Primary | G3829: S021 | H3829: PackChile Wholesale | I3829: 45787 | J3829: 21 | K3829: pack 50 | L3829: 3050 | M3829: 64050 | N3829: 68.5 | O3829: 49437 | P3829: Concrete | Q3829: Autumn

Sheet Batch_Outcomes
B1: Batch Outcomes — how each batch was sold or lost
B2: Keyed by BatchID: fully sold out, or partial loss with the wasted %.
B4: BatchID | C4: ProductID | D4: Category | E4: Status | F4: Qty Purchased | G4: Qty Sold | H4: Qty Wasted | I4: Wasted % | J4: Close Date | K4: Revenue (CLP) | L4: Revenue (USD) | M4: Batch Cost (CLP) | N4: Gross Profit (CLP) | O4: Gross Profit (USD) | P4: Waste Cost (CLP) | Q4: Purchase Date
B5: B00001 | C5: P001 | D5: Olives | E5: Partial Loss | F5: 16 | G5: 11.78 | H5: 4.22 | I5: 26.4 | J5: 45161 | K5: 47120 | L5: 50.4 | M5: 47200 | N5: -80 | O5: -0.09 | P5: =IF(COUNTIF(TblPurchases[BatchID],TblOutcomes[[#This Row],[BatchID]])<>1,"n.a.",TblOutcomes[[#This Row],[Qty Wasted]]*SUMIFS(TblPurchases[Unit Cost (CLP)],TblPurchases[BatchID],TblOutcomes[[#This Row],[BatchID]])) -> 12449 | Q5: =IF(COUNTIF(TblPurchases[BatchID],TblOutcomes[[#This Row],[BatchID]])<>1,"n.a.",SUMIFS(TblPurchases[Purchase Date],TblPurchases[BatchID],TblOutcomes[[#This Row],[BatchID]])) -> 45116
B6: B00002 | C6: P001 | D6: Olives | E6: Partial Loss | F6: 13 | G6: 11.63 | H6: 1.36 | I6: 10.5 | J6: 45172 | K6: 46520 | L6: 49.75 | M6: 38350 | N6: 8170 | O6: 8.74 | P6: =IF(COUNTIF(TblPurchases[BatchID],TblOutcomes[[#This Row],[BatchID]])<>1,"n.a.",TblOutcomes[[#This Row],[Qty Wasted]]*SUMIFS(TblPurchases[Unit Cost (CLP)],TblPurchases[BatchID],TblOutcomes[[#This Row],[BatchID]])) -> 4012 | Q6: =IF(COUNTIF(TblPurchases[BatchID],TblOutcomes[[#This Row],[BatchID]])<>1,"n.a.",SUMIFS(TblPurchases[Purchase Date],TblPurchases[BatchID],TblOutcomes[[#This Row],[BatchID]])) -> 45127
B7: B00003 | C7: P001 | D7: Olives | E7: Partial Loss | F7: 13 | G7: 11.63 | H7: 1.36 | I7: 10.5 | J7: 45181 | K7: 46520 | L7: 49.75 | M7: 38350 | N7: 8170 | O7: 8.74 | P7: =IF(COUNTIF(TblPurchases[BatchID],TblOutcomes[[#This Row],[BatchID]])<>1,"n.a.",TblOutcomes[[#This Row],[Qty Wasted]]*SUMIFS(TblPurchases[Unit Cost (CLP)],TblPurchases[BatchID],TblOutcomes[[#This Row],[BatchID]])) -> 4012 | Q7: =IF(COUNTIF(TblPurchases[BatchID],TblOutcomes[[#This Row],[BatchID]])<>1,"n.a.",SUMIFS(TblPurchases[Purchase Date],TblPurchases[BatchID],TblOutcomes[[#This Row],[BatchID]])) -> 45136
B8: B00004 | C8: P001 | D8: Olives | E8: Sold Out | F8: 16 | G8: 16 | H8: 0 | I8: 0 | J8: 45152 | K8: 64000 | L8: 68.45 | M8: 47200 | N8: 16800 | O8: 17.97 | P8: =IF(COUNTIF(TblPurchases[BatchID],TblOutcomes[[#This Row],[BatchID]])<>1,"n.a.",TblOutcomes[[#This Row],[Qty Wasted]]*SUMIFS(TblPurchases[Unit Cost (CLP)],TblPurchases[BatchID],TblOutcomes[[#This Row],[BatchID]])) -> 0 | Q8: =IF(COUNTIF(TblPurchases[BatchID],TblOutcomes[[#This Row],[BatchID]])<>1,"n.a.",SUMIFS(TblPurchases[Purchase Date],TblPurchases[BatchID],TblOutcomes[[#This Row],[BatchID]])) -> 45143
B9: B00005 | C9: P001 | D9: Olives | E9: Partial Loss | F9: 15 | G9: 10.52 | H9: 4.48 | I9: 29.9 | J9: 45196 | K9: 42080 | L9: 45.01 | M9: 44250 | N9: -2170 | O9: -2.32 | P9: =IF(COUNTIF(TblPurchases[BatchID],TblOutcomes[[#This Row],[BatchID]])<>1,"n.a.",TblOutcomes[[#This Row],[Qty Wasted]]*SUMIFS(TblPurchases[Unit Cost (CLP)],TblPurchases[BatchID],TblOutcomes[[#This Row],[BatchID]])) -> 13216 | Q9: =IF(COUNTIF(TblPurchases[BatchID],TblOutcomes[[#This Row],[BatchID]])<>1,"n.a.",SUMIFS(TblPurchases[Purchase Date],TblPurchases[BatchID],TblOutcomes[[#This Row],[BatchID]])) -> 45151
B10: B00006 | C10: P001 | D10: Olives | E10: Partial Loss | F10: 16 | G10: 13.58 | H10: 2.42 | I10: 15.1 | J10: 45204 | K10: 54320 | L10: 58.1 | M10: 47200 | N10: 7120 | O10: 7.61 | P10: =IF(COUNTIF(TblPurchases[BatchID],TblOutcomes[[#This Row],[BatchID]])<>1,"n.a.",TblOutcomes[[#This Row],[Qty Wasted]]*SUMIFS(TblPurchases[Unit Cost (CLP)],TblPurchases[BatchID],TblOutcomes[[#This Row],[BatchID]])) -> 7139 | Q10: =IF(COUNTIF(TblPurchases[BatchID],TblOutcomes[[#This Row],[BatchID]])<>1,"n.a.",SUMIFS(TblPurchases[Purchase Date],TblPurchases[BatchID],TblOutcomes[[#This Row],[BatchID]])) -> 45159
B11: B00007 | C11: P001 | D11: Olives | E11: Sold Out | F11: 17 | G11: 17 | H11: 0 | I11: 0 | J11: 45171 | K11: 68000 | L11: 72.73 | M11: 50150 | N11: 17850 | O11: 19.09 | P11: =IF(COUNTIF(TblPurchases[BatchID],TblOutcomes[[#This Row],[BatchID]])<>1,"n.a.",TblOutcomes[[#This Row],[Qty Wasted]]*SUMIFS(TblPurchases[Unit Cost (CLP)],TblPurchases[BatchID],TblOutcomes[[#This Row],[BatchID]])) -> 0 | Q11: =IF(COUNTIF(TblPurchases[BatchID],TblOutcomes[[#This Row],[BatchID]])<>1,"n.a.",SUMIFS(TblPurchases[Purchase Date],TblPurchases[BatchID],TblOutcomes[[#This Row],[BatchID]])) -> 45166
B12: B00008 | C12: P001 | D12: Olives | E12: Partial Loss | F12: 19 | G12: 16.72 | H12: 2.28 | I12: 12 | J12: 45220 | K12: 66880 | L12: 71.53 | M12: 57000 | N12: 9880 | O12: 10.57 | P12: =IF(COUNTIF(TblPurchases[BatchID],TblOutcomes[[#This Row],[BatchID]])<>1,"n.a.",TblOutcomes[[#This Row],[Qty Wasted]]*SUMIFS(TblPurchases[Unit Cost (CLP)],TblPurchases[BatchID],TblOutcomes[[#This Row],[BatchID]])) -> 6840 | Q12: =IF(COUNTIF(TblPurchases[BatchID],TblOutcomes[[#This Row],[BatchID]])<>1,"n.a.",SUMIFS(TblPurchases[Purchase Date],TblPurchases[BatchID],TblOutcomes[[#This Row],[BatchID]])) -> 45175
B13: B00009 | C13: P001 | D13: Olives | E13: Partial Loss | F13: 18 | G13: 14.89 | H13: 3.11 | I13: 17.3 | J13: 45230 | K13: 59560 | L13: 63.7 | M13: 53100 | N13: 6460 | O13: 6.91 | P13: =IF(COUNTIF(TblPurchases[BatchID],TblOutcomes[[#This Row],[BatchID]])<>1,"n.a.",TblOutcomes[[#This Row],[Qty Wasted]]*SUMIFS(TblPurchases[Unit Cost (CLP)],TblPurchases[BatchID],TblOutcomes[[#This Row],[BatchID]])) -> 9174.5 | Q13: =IF(COUNTIF(TblPurchases[BatchID],TblOutcomes[[#This Row],[BatchID]])<>1,"n.a.",SUMIFS(TblPurchases[Purchase Date],TblPurchases[BatchID],TblOutcomes[[#This Row],[BatchID]])) -> 45185
B14: B00010 | C14: P001 | D14: Olives | E14: Partial Loss | F14: 20 | G14: 16.44 | H14: 3.56 | I14: 17.8 | J14: 45239 | K14: 65760 | L14: 70.33 | M14: 59000 | N14: 6760 | O14: 7.23 | P14: =IF(COUNTIF(TblPurchases[BatchID],TblOutcomes[[#This Row],[BatchID]])<>1,"n.a.",TblOutcomes[[#This Row],[Qty Wasted]]*SUMIFS(TblPurchases[Unit Cost (CLP)],TblPurchases[BatchID],TblOutcomes[[#This Row],[BatchID]])) -> 10502 | Q14: =IF(COUNTIF(TblPurchases[BatchID],TblOutcomes[[#This Row],[BatchID]])<>1,"n.a.",SUMIFS(TblPurchases[Purchase Date],TblPurchases[BatchID],TblOutcomes[[#This Row],[BatchID]])) -> 45194
B15: B00011 | C15: P001 | D15: Olives | E15: Sold Out | F15: 35 | G15: 35 | H15: 0 | I15: 0 | J15: 45210 | K15: 140000 | L15: 149.73 | M15: 103250 | N15: 36750 | O15: 39.3 | P15: =IF(COUNTIF(TblPurchases[BatchID],TblOutcomes[[#This Row],[BatchID]])<>1,"n.a.",TblOutcomes[[#This Row],[Qty Wasted]]*SUMIFS(TblPurchases[Unit Cost (CLP)],TblPurchases[BatchID],TblOutcomes[[#This Row],[BatchID]])) -> 0 | Q15: =IF(COUNTIF(TblPurchases[BatchID],TblOutcomes[[#This Row],[BatchID]])<>1,"n.a.",SUMIFS(TblPurchases[Purchase Date],TblPurchases[BatchID],TblOutcomes[[#This Row],[BatchID]])) -> 45203
B16: B00012 | C16: P001 | D16: Olives | E16: Sold Out | F16: 34 | G16: 34 | H16: 0 | I16: 0 | J16: 45222 | K16: 136000 | L16: 145.45 | M16: 100300 | N16: 35700 | O16: 38.18 | P16: =IF(COUNTIF(TblPurchases[BatchID],TblOutcomes[[#This Row],[BatchID]])<>1,"n.a.",TblOutcomes[[#This Row],[Qty Wasted]]*SUMIFS(TblPurchases[Unit Cost (CLP)],TblPurchases[BatchID],TblOutcomes[[#This Row],[BatchID]])) -> 0 | Q16: =IF(COUNTIF(TblPurchases[BatchID],TblOutcomes[[#This Row],[BatchID]])<>1,"n.a.",SUMIFS(TblPurchases[Purchase Date],TblPurchases[BatchID],TblOutcomes[[#This Row],[BatchID]])) -> 45211
... B3829: B03825 | C3829: P128 | D3829: Packaging | E3829: Sold Out | F3829: 21 | G3829: 21 | H3829: 0 | I3829: 0 | J3829: 45842 | K3829: 94500 | L3829: 101.07 | M3829: 64050 | N3829: 30450 | O3829: 32.57 | P3829: =IF(COUNTIF(TblPurchases[BatchID],TblOutcomes[[#This Row],[BatchID]])<>1,"n.a.",TblOutcomes[[#This Row],[Qty Wasted]]*SUMIFS(TblPurchases[Unit Cost (CLP)],TblPurchases[BatchID],TblOutcomes[[#This Row],[BatchID]])) -> 0 | Q3829: =IF(COUNTIF(TblPurchases[BatchID],TblOutcomes[[#This Row],[BatchID]])<>1,"n.a.",SUMIFS(TblPurchases[Purchase Date],TblPurchases[BatchID],TblOutcomes[[#This Row],[BatchID]])) -> 45787

Sheet Supplier_Scorecard
B1: Supplier Scorecard — supply-chain dependency & performance
B2: Based on PRIMARY links. Updates automatically from Supply_Links / Products.
B4: Supplier | C4: # Products (primary) | D4: # Essential | E4: Avg Lead Time (days) | F4: Avg Margin (%) | G4: Delivery? | H4: Dependency Risk
B5: Curico Chili & Sauces | C5: =COUNTIFS(TblSupply[Supplier],B5,TblSupply[SupplierRole],"Primary") -> 9 | D5: =SUMPRODUCT((TblSupply[Supplier]=B5)*(TblSupply[SupplierRole]="Primary")*COUNTIFS(TblProducts[ID],TblSupply[ProductID],TblProducts[Essential],"Yes")) -> 2 | E5: =IFERROR(AVERAGEIFS(TblSupply[Lead Time (days)],TblSupply[Supplier],B5,TblSupply[SupplierRole],"Primary"),0) -> 1.6666667 | F5: =IFERROR(SUMPRODUCT((TblSupply[Supplier]=B5)*(TblSupply[SupplierRole]="Primary")*SUMIFS(TblProducts[Margin (%)],TblProducts[ID],TblSupply[ProductID]))/C5,0) -> 0.29537037 | G5: =IFERROR(INDEX(TblSuppliers[Delivery?],MATCH(B5,TblSuppliers[Supplier],0)),"") -> No | H5: =IF(D5>=3,"High",IF(D5>=1,"Medium","Low")) -> Medium
B6: Doña Rosa Pickles | C6: =COUNTIFS(TblSupply[Supplier],B6,TblSupply[SupplierRole],"Primary") -> 5 | D6: =SUMPRODUCT((TblSupply[Supplier]=B6)*(TblSupply[SupplierRole]="Primary")*COUNTIFS(TblProducts[ID],TblSupply[ProductID],TblProducts[Essential],"Yes")) -> 0 | E6: =IFERROR(AVERAGEIFS(TblSupply[Lead Time (days)],TblSupply[Supplier],B6,TblSupply[SupplierRole],"Primary"),0) -> 2.2 | F6: =IFERROR(SUMPRODUCT((TblSupply[Supplier]=B6)*(TblSupply[SupplierRole]="Primary")*SUMIFS(TblProducts[Margin (%)],TblProducts[ID],TblSupply[ProductID]))/C6,0) -> 0.29933333 | G6: =IFERROR(INDEX(TblSuppliers[Delivery?],MATCH(B6,TblSuppliers[Supplier],0)),"") -> Yes | H6: =IF(D6>=3,"High",IF(D6>=1,"Medium","Low")) -> Low
B7: El Olivar Olives Ltd. | C7: =COUNTIFS(TblSupply[Supplier],B7,TblSupply[SupplierRole],"Primary") -> 11 | D7: =SUMPRODUCT((TblSupply[Supplier]=B7)*(TblSupply[SupplierRole]="Primary")*COUNTIFS(TblProducts[ID],TblSupply[ProductID],TblProducts[Essential],"Yes")) -> 4 | E7: =IFERROR(AVERAGEIFS(TblSupply[Lead Time (days)],TblSupply[Supplier],B7,TblSupply[SupplierRole],"Primary"),0) -> 2.1818182 | F7: =IFERROR(SUMPRODUCT((TblSupply[Supplier]=B7)*(TblSupply[SupplierRole]="Primary")*SUMIFS(TblProducts[Margin (%)],TblProducts[ID],TblSupply[ProductID]))/C7,0) -> 0.28732684 | G7: =IFERROR(INDEX(TblSuppliers[Delivery?],MATCH(B7,TblSuppliers[Supplier],0)),"") -> Yes | H7: =IF(D7>=3,"High",IF(D7>=1,"Medium","Low")) -> High
B8: Los Ulmos Apiary | C8: =COUNTIFS(TblSupply[Supplier],B8,TblSupply[SupplierRole],"Primary") -> 5 | D8: =SUMPRODUCT((TblSupply[Supplier]=B8)*(TblSupply[SupplierRole]="Primary")*COUNTIFS(TblProducts[ID],TblSupply[ProductID],TblProducts[Essential],"Yes")) -> 1 | E8: =IFERROR(AVERAGEIFS(TblSupply[Lead Time (days)],TblSupply[Supplier],B8,TblSupply[SupplierRole],"Primary"),0) -> 2.2 | F8: =IFERROR(SUMPRODUCT((TblSupply[Supplier]=B8)*(TblSupply[SupplierRole]="Primary")*SUMIFS(TblProducts[Margin (%)],TblProducts[ID],TblSupply[ProductID]))/C8,0) -> 0.2952634 | G8: =IFERROR(INDEX(TblSuppliers[Delivery?],MATCH(B8,TblSuppliers[Supplier],0)),"") -> No | H8: =IF(D8>=3,"High",IF(D8>=1,"Medium","Low")) -> Medium
B9: Maipo Nuts Ltd. | C9: =COUNTIFS(TblSupply[Supplier],B9,TblSupply[SupplierRole],"Primary") -> 34 | D9: =SUMPRODUCT((TblSupply[Supplier]=B9)*(TblSupply[SupplierRole]="Primary")*COUNTIFS(TblProducts[ID],TblSupply[ProductID],TblProducts[Essential],"Yes")) -> 2 | E9: =IFERROR(AVERAGEIFS(TblSupply[Lead Time (days)],TblSupply[Supplier],B9,TblSupply[SupplierRole],"Primary"),0) -> 1.6176471 | F9: =IFERROR(SUMPRODUCT((TblSupply[Supplier]=B9)*(TblSupply[SupplierRole]="Primary")*SUMIFS(TblProducts[Margin (%)],TblProducts[ID],TblSupply[ProductID]))/C9,0) -> 0.26483908 | G9: =IFERROR(INDEX(TblSuppliers[Delivery?],MATCH(B9,TblSuppliers[Supplier],0)),"") -> Yes | H9: =IF(D9>=3,"High",IF(D9>=1,"Medium","Low")) -> Medium
B10: Molina Artisan Sweets | C10: =COUNTIFS(TblSupply[Supplier],B10,TblSupply[SupplierRole],"Primary") -> 17 | D10: =SUMPRODUCT((TblSupply[Supplier]=B10)*(TblSupply[SupplierRole]="Primary")*COUNTIFS(TblProducts[ID],TblSupply[ProductID],TblProducts[Essential],"Yes")) -> 0 | E10: =IFERROR(AVERAGEIFS(TblSupply[Lead Time (days)],TblSupply[Supplier],B10,TblSupply[SupplierRole],"Primary"),0) -> 2.1764706 | F10: =IFERROR(SUMPRODUCT((TblSupply[Supplier]=B10)*(TblSupply[SupplierRole]="Primary")*SUMIFS(TblProducts[Margin (%)],TblProducts[ID],TblSupply[ProductID]))/C10,0) -> 0.31323529 | G10: =IFERROR(INDEX(TblSuppliers[Delivery?],MATCH(B10,TblSuppliers[Supplier],0)),"") -> No | H10: =IF(D10>=3,"High",IF(D10>=1,"Medium","Low")) -> Low
B11: PackChile Wholesale | C11: =COUNTIFS(TblSupply[Supplier],B11,TblSupply[SupplierRole],"Primary") -> 17 | D11: =SUMPRODUCT((TblSupply[Supplier]=B11)*(TblSupply[SupplierRole]="Primary")*COUNTIFS(TblProducts[ID],TblSupply[ProductID],TblProducts[Essential],"Yes")) -> 0 | E11: =IFERROR(AVERAGEIFS(TblSupply[Lead Time (days)],TblSupply[Supplier],B11,TblSupply[SupplierRole],"Primary"),0) -> 1.4117647 | F11: =IFERROR(SUMPRODUCT((TblSupply[Supplier]=B11)*(TblSupply[SupplierRole]="Primary")*SUMIFS(TblProducts[Margin (%)],TblProducts[ID],TblSupply[ProductID]))/C11,0) -> 0.33387128 | G11: =IFERROR(INDEX(TblSuppliers[Delivery?],MATCH(B11,TblSuppliers[Supplier],0)),"") -> Yes | H11: =IF(D11>=3,"High",IF(D11>=1,"Medium","Low")) -> Low
B12: San Fernando Dried Goods | C12: =COUNTIFS(TblSupply[Supplier],B12,TblSupply[SupplierRole],"Primary") -> 15 | D12: =SUMPRODUCT((TblSupply[Supplier]=B12)*(TblSupply[SupplierRole]="Primary")*COUNTIFS(TblProducts[ID],TblSupply[ProductID],TblProducts[Essential],"Yes")) -> 3 | E12: =IFERROR(AVERAGEIFS(TblSupply[Lead Time (days)],TblSupply[Supplier],B12,TblSupply[SupplierRole],"Primary"),0) -> 1.6 | F12: =IFERROR(SUMPRODUCT((TblSupply[Supplier]=B12)*(TblSupply[SupplierRole]="Primary")*SUMIFS(TblProducts[Margin (%)],TblProducts[ID],TblSupply[ProductID]))/C12,0) -> 0.27682853 | G12: =IFERROR(INDEX(TblSuppliers[Delivery?],MATCH(B12,TblSuppliers[Supplier],0)),"") -> Yes | H12: =IF(D12>=3,"High",IF(D12>=1,"Medium","Low")) -> High
B13: San Vicente Grains & Legumes | C13: =COUNTIFS(TblSupply[Supplier],B13,TblSupply[SupplierRole],"Primary") -> 4 | D13: =SUMPRODUCT((TblSupply[Supplier]=B13)*(TblSupply[SupplierRole]="Primary")*COUNTIFS(TblProducts[ID],TblSupply[ProductID],TblProducts[Essential],"Yes")) -> 1 | E13: =IFERROR(AVERAGEIFS(TblSupply[Lead Time (days)],TblSupply[Supplier],B13,TblSupply[SupplierRole],"Primary"),0) -> 1.75 | F13: =IFERROR(SUMPRODUCT((TblSupply[Supplier]=B13)*(TblSupply[SupplierRole]="Primary")*SUMIFS(TblProducts[Margin (%)],TblProducts[ID],TblSupply[ProductID]))/C13,0) -> 0.26041667 | G13: =IFERROR(INDEX(TblSuppliers[Delivery?],MATCH(B13,TblSuppliers[Supplier],0)),"") -> No | H13: =IF(D13>=3,"High",IF(D13>=1,"Medium","Low")) -> Medium
B14: Valley Spices SpA | C14: =COUNTIFS(TblSupply[Supplier],B14,TblSupply[SupplierRole],"Primary") -> 11 | D14: =SUMPRODUCT((TblSupply[Supplier]=B14)*(TblSupply[SupplierRole]="Primary")*COUNTIFS(TblProducts[ID],TblSupply[ProductID],TblProducts[Essential],"Yes")) -> 2 | E14: =IFERROR(AVERAGEIFS(TblSupply[Lead Time (days)],TblSupply[Supplier],B14,TblSupply[SupplierRole],"Primary"),0) -> 1.6363636 | F14: =IFERROR(SUMPRODUCT((TblSupply[Supplier]=B14)*(TblSupply[SupplierRole]="Primary")*SUMIFS(TblProducts[Margin (%)],TblProducts[ID],TblSupply[ProductID]))/C14,0) -> 0.30757576 | G14: =IFERROR(INDEX(TblSuppliers[Delivery?],MATCH(B14,TblSuppliers[Supplier],0)),"") -> Yes | H14: =IF(D14>=3,"High",IF(D14>=1,"Medium","Low")) -> Medium

Sheet Category_Summary
B1: Category Summary
B2: Pivot-style; recalculates from Products. Includes 2-year revenue & waste from Batch_Outcomes.
B4: Category | C4: # Products | D4: # Essential | E4: Avg Price (CLP) | F4: Avg Margin (%) | G4: Cohort revenue CLP | H4: Waste cost % | I4: Stock High | J4: Stock Med | K4: Stock Low
B5: Candy | C5: =COUNTIFS(TblProducts[Category],B5) -> 17 | D5: =COUNTIFS(TblProducts[Category],B5,TblProducts[Essential],"Yes") -> 0 | E5: =AVERAGEIFS(TblProducts[Sale Price (CLP)],TblProducts[Category],B5) -> 1088.2353 | F5: =AVERAGEIFS(TblProducts[Margin (%)],TblProducts[Category],B5) -> 0.31323529 | G5: =SUMIFS(TblOutcomes[Revenue (CLP)],TblOutcomes[Category],B5) -> 15758630 | H5: =IF(SUMIFS(TblOutcomes[Batch Cost (CLP)],TblOutcomes[Category],B5)=0,"n.a.",SUMIFS(TblOutcomes[Waste Cost (CLP)],TblOutcomes[Category],B5)/SUMIFS(TblOutcomes[Batch Cost (CLP)],TblOutcomes[Category],B5)) -> 0.014816193 | I5: =COUNTIFS(TblProducts[Category],B5,TblProducts[Current Stock],"High") -> 8 | J5: =COUNTIFS(TblProducts[Category],B5,TblProducts[Current Stock],"Medium") -> 7 | K5: =COUNTIFS(TblProducts[Category],B5,TblProducts[Current Stock],"Low") -> 2
B6: Chili | C6: =COUNTIFS(TblProducts[Category],B6) -> 9 | D6: =COUNTIFS(TblProducts[Category],B6,TblProducts[Essential],"Yes") -> 2 | E6: =AVERAGEIFS(TblProducts[Sale Price (CLP)],TblProducts[Category],B6) -> 1888.8889 | F6: =AVERAGEIFS(TblProducts[Margin (%)],TblProducts[Category],B6) -> 0.29537037 | G6: =SUMIFS(TblOutcomes[Revenue (CLP)],TblOutcomes[Category],B6) -> 17309965 | H6: =IF(SUMIFS(TblOutcomes[Batch Cost (CLP)],TblOutcomes[Category],B6)=0,"n.a.",SUMIFS(TblOutcomes[Waste Cost (CLP)],TblOutcomes[Category],B6)/SUMIFS(TblOutcomes[Batch Cost (CLP)],TblOutcomes[Category],B6)) -> 0.0071600042 | I6: =COUNTIFS(TblProducts[Category],B6,TblProducts[Current Stock],"High") -> 4 | J6: =COUNTIFS(TblProducts[Category],B6,TblProducts[Current Stock],"Medium") -> 5 | K6: =COUNTIFS(TblProducts[Category],B6,TblProducts[Current Stock],"Low") -> 0
B7: Dried Fruit | C7: =COUNTIFS(TblProducts[Category],B7) -> 12 | D7: =COUNTIFS(TblProducts[Category],B7,TblProducts[Essential],"Yes") -> 2 | E7: =AVERAGEIFS(TblProducts[Sale Price (CLP)],TblProducts[Category],B7) -> 6458.3333 | F7: =AVERAGEIFS(TblProducts[Margin (%)],TblProducts[Category],B7) -> 0.27928963 | G7: =SUMIFS(TblOutcomes[Revenue (CLP)],TblOutcomes[Category],B7) -> 29169700 | H7: =IF(SUMIFS(TblOutcomes[Batch Cost (CLP)],TblOutcomes[Category],B7)=0,"n.a.",SUMIFS(TblOutcomes[Waste Cost (CLP)],TblOutcomes[Category],B7)/SUMIFS(TblOutcomes[Batch Cost (CLP)],TblOutcomes[Category],B7)) -> 0.014679421 | I7: =COUNTIFS(TblProducts[Category],B7,TblProducts[Current Stock],"High") -> 6 | J7: =COUNTIFS(TblProducts[Category],B7,TblProducts[Current Stock],"Medium") -> 5 | K7: =COUNTIFS(TblProducts[Category],B7,TblProducts[Current Stock],"Low") -> 1
B8: Grains | C8: =COUNTIFS(TblProducts[Category],B8) -> 4 | D8: =COUNTIFS(TblProducts[Category],B8,TblProducts[Essential],"Yes") -> 1 | E8: =AVERAGEIFS(TblProducts[Sale Price (CLP)],TblProducts[Category],B8) -> 1625 | F8: =AVERAGEIFS(TblProducts[Margin (%)],TblProducts[Category],B8) -> 0.26041667 | G8: =SUMIFS(TblOutcomes[Revenue (CLP)],TblOutcomes[Category],B8) -> 22779295 | H8: =IF(SUMIFS(TblOutcomes[Batch Cost (CLP)],TblOutcomes[Category],B8)=0,"n.a.",SUMIFS(TblOutcomes[Waste Cost (CLP)],TblOutcomes[Category],B8)/SUMIFS(TblOutcomes[Batch Cost (CLP)],TblOutcomes[Category],B8)) -> 0.091796684 | I8: =COUNTIFS(TblProducts[Category],B8,TblProducts[Current Stock],"High") -> 2 | J8: =COUNTIFS(TblProducts[Category],B8,TblProducts[Current Stock],"Medium") -> 0 | K8: =COUNTIFS(TblProducts[Category],B8,TblProducts[Current Stock],"Low") -> 2
B9: Honey | C9: =COUNTIFS(TblProducts[Category],B9) -> 5 | D9: =COUNTIFS(TblProducts[Category],B9,TblProducts[Essential],"Yes") -> 1 | E9: =AVERAGEIFS(TblProducts[Sale Price (CLP)],TblProducts[Category],B9) -> 5500 | F9: =AVERAGEIFS(TblProducts[Margin (%)],TblProducts[Category],B9) -> 0.2952634 | G9: =SUMIFS(TblOutcomes[Revenue (CLP)],TblOutcomes[Category],B9) -> 8856595 | H9: =IF(SUMIFS(TblOutcomes[Batch Cost (CLP)],TblOutcomes[Category],B9)=0,"n.a.",SUMIFS(TblOutcomes[Waste Cost (CLP)],TblOutcomes[Category],B9)/SUMIFS(TblOutcomes[Batch Cost (CLP)],TblOutcomes[Category],B9)) -> 0.0087380766 | I9: =COUNTIFS(TblProducts[Category],B9,TblProducts[Current Stock],"High") -> 3 | J9: =COUNTIFS(TblProducts[Category],B9,TblProducts[Current Stock],"Medium") -> 1 | K9: =COUNTIFS(TblProducts[Category],B9,TblProducts[Current Stock],"Low") -> 1
B10: Nuts | C10: =COUNTIFS(TblProducts[Category],B10) -> 15 | D10: =COUNTIFS(TblProducts[Category],B10,TblProducts[Essential],"Yes") -> 1 | E10: =AVERAGEIFS(TblProducts[Sale Price (CLP)],TblProducts[Category],B10) -> 17366.667 | F10: =AVERAGEIFS(TblProducts[Margin (%)],TblProducts[Category],B10) -> 0.24806928 | G10: =SUMIFS(TblOutcomes[Revenue (CLP)],TblOutcomes[Category],B10) -> 127910830 | H10: =IF(SUMIFS(TblOutcomes[Batch Cost (CLP)],TblOutcomes[Category],B10)=0,"n.a.",SUMIFS(TblOutcomes[Waste Cost (CLP)],TblOutcomes[Category],B10)/SUMIFS(TblOutcomes[Batch Cost (CLP)],TblOutcomes[Category],B10)) -> 0.019496347 | I10: =COUNTIFS(TblProducts[Category],B10,TblProducts[Current Stock],"High") -> 10 | J10: =COUNTIFS(TblProducts[Category],B10,TblProducts[Current Stock],"Medium") -> 2 | K10: =COUNTIFS(TblProducts[Category],B10,TblProducts[Current Stock],"Low") -> 3
B11: Olives | C11: =COUNTIFS(TblProducts[Category],B11) -> 11 | D11: =COUNTIFS(TblProducts[Category],B11,TblProducts[Essential],"Yes") -> 4 | E11: =AVERAGEIFS(TblProducts[Sale Price (CLP)],TblProducts[Category],B11) -> 3227.2727 | F11: =AVERAGEIFS(TblProducts[Margin (%)],TblProducts[Category],B11) -> 0.28732684 | G11: =SUMIFS(TblOutcomes[Revenue (CLP)],TblOutcomes[Category],B11) -> 74726140 | H11: =IF(SUMIFS(TblOutcomes[Batch Cost (CLP)],TblOutcomes[Category],B11)=0,"n.a.",SUMIFS(TblOutcomes[Waste Cost (CLP)],TblOutcomes[Category],B11)/SUMIFS(TblOutcomes[Batch Cost (CLP)],TblOutcomes[Category],B11)) -> 0.052821244 | I11: =COUNTIFS(TblProducts[Category],B11,TblProducts[Current Stock],"High") -> 5 | J11: =COUNTIFS(TblProducts[Category],B11,TblProducts[Current Stock],"Medium") -> 4 | K11: =COUNTIFS(TblProducts[Category],B11,TblProducts[Current Stock],"Low") -> 2
B12: Packaging | C12: =COUNTIFS(TblProducts[Category],B12) -> 17 | D12: =COUNTIFS(TblProducts[Category],B12,TblProducts[Essential],"Yes") -> 0 | E12: =AVERAGEIFS(TblProducts[Sale Price (CLP)],TblProducts[Category],B12) -> 3058.8235 | F12: =AVERAGEIFS(TblProducts[Margin (%)],TblProducts[Category],B12) -> 0.33387128 | G12: =SUMIFS(TblOutcomes[Revenue (CLP)],TblOutcomes[Category],B12) -> 13950000 | H12: =IF(SUMIFS(TblOutcomes[Batch Cost (CLP)],TblOutcomes[Category],B12)=0,"n.a.",SUMIFS(TblOutcomes[Waste Cost (CLP)],TblOutcomes[Category],B12)/SUMIFS(TblOutcomes[Batch Cost (CLP)],TblOutcomes[Category],B12)) -> 0 | I12: =COUNTIFS(TblProducts[Category],B12,TblProducts[Current Stock],"High") -> 6 | J12: =COUNTIFS(TblProducts[Category],B12,TblProducts[Current Stock],"Medium") -> 2 | K12: =COUNTIFS(TblProducts[Category],B12,TblProducts[Current Stock],"Low") -> 9
B13: Peanuts | C13: =COUNTIFS(TblProducts[Category],B13) -> 9 | D13: =COUNTIFS(TblProducts[Category],B13,TblProducts[Essential],"Yes") -> 1 | E13: =AVERAGEIFS(TblProducts[Sale Price (CLP)],TblProducts[Category],B13) -> 7944.4444 | F13: =AVERAGEIFS(TblProducts[Margin (%)],TblProducts[Category],B13) -> 0.28595589 | G13: =SUMIFS(TblOutcomes[Revenue (CLP)],TblOutcomes[Category],B13) -> 54233565 | H13: =IF(SUMIFS(TblOutcomes[Batch Cost (CLP)],TblOutcomes[Category],B13)=0,"n.a.",SUMIFS(TblOutcomes[Waste Cost (CLP)],TblOutcomes[Category],B13)/SUMIFS(TblOutcomes[Batch Cost (CLP)],TblOutcomes[Category],B13)) -> 0.02863971 | I13: =COUNTIFS(TblProducts[Category],B13,TblProducts[Current Stock],"High") -> 2 | J13: =COUNTIFS(TblProducts[Category],B13,TblProducts[Current Stock],"Medium") -> 4 | K13: =COUNTIFS(TblProducts[Category],B13,TblProducts[Current Stock],"Low") -> 3
B14: Pickles | C14: =COUNTIFS(TblProducts[Category],B14) -> 5 | D14: =COUNTIFS(TblProducts[Category],B14,TblProducts[Essential],"Yes") -> 0 | E14: =AVERAGEIFS(TblProducts[Sale Price (CLP)],TblProducts[Category],B14) -> 2800 | F14: =AVERAGEIFS(TblProducts[Margin (%)],TblProducts[Category],B14) -> 0.29933333 | G14: =SUMIFS(TblOutcomes[Revenue (CLP)],TblOutcomes[Category],B14) -> 7479415 | H14: =IF(SUMIFS(TblOutcomes[Batch Cost (CLP)],TblOutcomes[Category],B14)=0,"n.a.",SUMIFS(TblOutcomes[Waste Cost (CLP)],TblOutcomes[Category],B14)/SUMIFS(TblOutcomes[Batch Cost (CLP)],TblOutcomes[Category],B14)) -> 0.011721292 | I14: =COUNTIFS(TblProducts[Category],B14,TblProducts[Current Stock],"High") -> 4 | J14: =COUNTIFS(TblProducts[Category],B14,TblProducts[Current Stock],"Medium") -> 1 | K14: =COUNTIFS(TblProducts[Category],B14,TblProducts[Current Stock],"Low") -> 0
B15: Raisins | C15: =COUNTIFS(TblProducts[Category],B15) -> 3 | D15: =COUNTIFS(TblProducts[Category],B15,TblProducts[Essential],"Yes") -> 1 | E15: =AVERAGEIFS(TblProducts[Sale Price (CLP)],TblProducts[Category],B15) -> 7500 | F15: =AVERAGEIFS(TblProducts[Margin (%)],TblProducts[Category],B15) -> 0.26698413 | G15: =SUMIFS(TblOutcomes[Revenue (CLP)],TblOutcomes[Category],B15) -> 8632580 | H15: =IF(SUMIFS(TblOutcomes[Batch Cost (CLP)],TblOutcomes[Category],B15)=0,"n.a.",SUMIFS(TblOutcomes[Waste Cost (CLP)],TblOutcomes[Category],B15)/SUMIFS(TblOutcomes[Batch Cost (CLP)],TblOutcomes[Category],B15)) -> 0.0088712808 | I15: =COUNTIFS(TblProducts[Category],B15,TblProducts[Current Stock],"High") -> 0 | J15: =COUNTIFS(TblProducts[Category],B15,TblProducts[Current Stock],"Medium") -> 3 | K15: =COUNTIFS(TblProducts[Category],B15,TblProducts[Current Stock],"Low") -> 0
B16: Seasonings | C16: =COUNTIFS(TblProducts[Category],B16) -> 11 | D16: =COUNTIFS(TblProducts[Category],B16,TblProducts[Essential],"Yes") -> 2 | E16: =AVERAGEIFS(TblProducts[Sale Price (CLP)],TblProducts[Category],B16) -> 1500 | F16: =AVERAGEIFS(TblProducts[Margin (%)],TblProducts[Category],B16) -> 0.30757576 | G16: =SUMIFS(TblOutcomes[Revenue (CLP)],TblOutcomes[Category],B16) -> 10703465 | H16: =IF(SUMIFS(TblOutcomes[Batch Cost (CLP)],TblOutcomes[Category],B16)=0,"n.a.",SUMIFS(TblOutcomes[Waste Cost (CLP)],TblOutcomes[Category],B16)/SUMIFS(TblOutcomes[Batch Cost (CLP)],TblOutcomes[Category],B16)) -> 0.0041870371 | I16: =COUNTIFS(TblProducts[Category],B16,TblProducts[Current Stock],"High") -> 6 | J16: =COUNTIFS(TblProducts[Category],B16,TblProducts[Current Stock],"Medium") -> 2 | K16: =COUNTIFS(TblProducts[Category],B16,TblProducts[Current Stock],"Low") -> 3
... B18: Trail Mix | C18: =COUNTIFS(TblProducts[Category],B18) -> 5 | D18: =COUNTIFS(TblProducts[Category],B18,TblProducts[Essential],"Yes") -> 0 | E18: =AVERAGEIFS(TblProducts[Sale Price (CLP)],TblProducts[Category],B18) -> 8900 | F18: =AVERAGEIFS(TblProducts[Margin (%)],TblProducts[Category],B18) -> 0.26235827 | G18: =SUMIFS(TblOutcomes[Revenue (CLP)],TblOutcomes[Category],B18) -> 16325210 | H18: =IF(SUMIFS(TblOutcomes[Batch Cost (CLP)],TblOutcomes[Category],B18)=0,"n.a.",SUMIFS(TblOutcomes[Waste Cost (CLP)],TblOutcomes[Category],B18)/SUMIFS(TblOutcomes[Batch Cost (CLP)],TblOutcomes[Category],B18)) -> 0.030593673 | I18: =COUNTIFS(TblProducts[Category],B18,TblProducts[Current Stock],"High") -> 4 | J18: =COUNTIFS(TblProducts[Category],B18,TblProducts[Current Stock],"Medium") -> 1 | K18: =COUNTIFS(TblProducts[Category],B18,TblProducts[Current Stock],"Low") -> 0
B19: TOTAL | C19: =SUM(C5:C18) -> 128 | D19: =SUM(D5:D18) -> 15 | E19: =AVERAGE(TblProducts[Sale Price (CLP)]) -> 5367.1875 | F19: =AVERAGE(TblProducts[Margin (%)]) -> 0.29198969 | G19: =SUM(G5:G18) -> 412926945 | H19: =IF(SUMIFS(TblOutcomes[Batch Cost (CLP)],TblOutcomes[Category],B19)=0,"n.a.",SUMIFS(TblOutcomes[Waste Cost (CLP)],TblOutcomes[Category],B19)/SUMIFS(TblOutcomes[Batch Cost (CLP)],TblOutcomes[Category],B19)) -> n.a. | I19: =SUM(I5:I18) -> 62 | J19: =SUM(J5:J18) -> 38 | K19: =SUM(K5:K18) -> 28

Sheet Season_Demand
B1: Season Demand
B2: Catalog seasonality assumptions. This is not measured sales demand.
B4: Peak Season | C4: # Products | D4: # Essential | E4: % of Catalog | F4: Avg Price (CLP) | G4: Avg Margin (%) | H4: Stock High | I4: Stock Med | J4: Stock Low
B5: Spring-Summer | C5: =COUNTIFS(TblProducts[Peak Season],B5) -> 13 | D5: =COUNTIFS(TblProducts[Peak Season],B5,TblProducts[Essential],"Yes") -> 5 | E5: =C5/COUNTA(TblProducts[ID]) -> 0.1015625 | F5: =AVERAGEIFS(TblProducts[Sale Price (CLP)],TblProducts[Peak Season],B5) -> 2807.6923 | G5: =AVERAGEIFS(TblProducts[Margin (%)],TblProducts[Peak Season],B5) -> 0.28011905 | H5: =COUNTIFS(TblProducts[Peak Season],B5,TblProducts[Current Stock],"High") -> 5 | I5: =COUNTIFS(TblProducts[Peak Season],B5,TblProducts[Current Stock],"Medium") -> 4 | J5: =COUNTIFS(TblProducts[Peak Season],B5,TblProducts[Current Stock],"Low") -> 4
B6: Fall-Winter | C6: =COUNTIFS(TblProducts[Peak Season],B6) -> 40 | D6: =COUNTIFS(TblProducts[Peak Season],B6,TblProducts[Essential],"Yes") -> 4 | E6: =C6/COUNTA(TblProducts[ID]) -> 0.3125 | F6: =AVERAGEIFS(TblProducts[Sale Price (CLP)],TblProducts[Peak Season],B6) -> 9687.5 | G6: =AVERAGEIFS(TblProducts[Margin (%)],TblProducts[Peak Season],B6) -> 0.27087438 | H6: =COUNTIFS(TblProducts[Peak Season],B6,TblProducts[Current Stock],"High") -> 21 | I6: =COUNTIFS(TblProducts[Peak Season],B6,TblProducts[Current Stock],"Medium") -> 15 | J6: =COUNTIFS(TblProducts[Peak Season],B6,TblProducts[Current Stock],"Low") -> 4
B7: All year | C7: =COUNTIFS(TblProducts[Peak Season],B7) -> 75 | D7: =COUNTIFS(TblProducts[Peak Season],B7,TblProducts[Essential],"Yes") -> 6 | E7: =C7/COUNTA(TblProducts[ID]) -> 0.5859375 | F7: =AVERAGEIFS(TblProducts[Sale Price (CLP)],TblProducts[Peak Season],B7) -> 3506.6667 | G7: =AVERAGEIFS(TblProducts[Margin (%)],TblProducts[Peak Season],B7) -> 0.30530877 | H7: =COUNTIFS(TblProducts[Peak Season],B7,TblProducts[Current Stock],"High") -> 36 | I7: =COUNTIFS(TblProducts[Peak Season],B7,TblProducts[Current Stock],"Medium") -> 19 | J7: =COUNTIFS(TblProducts[Peak Season],B7,TblProducts[Current Stock],"Low") -> 20

Sheet Restock_Alerts
B1: Restock Alerts
B2: Qualitative stock triage only. Count on-hand and incoming stock before ordering.
B4: ID | C4: Product | D4: Category | E4: Essential | F4: Current Stock | G4: Peak Season | H4: Reorder Priority | I4: Primary Supplier | J4: Phone | K4: Delivery?
B5: =Products!B4 -> P001 | C5: =Products!C4 -> Olives 120/140 (extra large), brined | D5: =Products!D4 -> Olives | E5: =Products!G4 -> Yes | F5: =Products!I4 -> High | G5: =Products!H4 -> Spring-Summer | H5: =IF(E5="Yes",IF(F5="Low","URGENT",IF(F5="Medium","Watch","OK")),"Low priority") -> OK | I5: =IFERROR(INDEX(TblSupply[Supplier],MATCH(1,INDEX((TblSupply[ProductID]=B5)*(TblSupply[SupplierRole]="Primary"),0),0)),"") -> El Olivar Olives Ltd. | J5: =IFERROR(INDEX(TblSuppliers[Phone],MATCH(I5,TblSuppliers[Supplier],0)),"") -> +56 9 5511 2233 | K5: =IFERROR(INDEX(TblSuppliers[Delivery?],MATCH(I5,TblSuppliers[Supplier],0)),"") -> Yes
B6: =Products!B5 -> P002 | C6: =Products!C5 -> Olives 140/160 (large), brined | D6: =Products!D5 -> Olives | E6: =Products!G5 -> Yes | F6: =Products!I5 -> Low | G6: =Products!H5 -> Spring-Summer | H6: =IF(E6="Yes",IF(F6="Low","URGENT",IF(F6="Medium","Watch","OK")),"Low priority") -> URGENT | I6: =IFERROR(INDEX(TblSupply[Supplier],MATCH(1,INDEX((TblSupply[ProductID]=B6)*(TblSupply[SupplierRole]="Primary"),0),0)),"") -> El Olivar Olives Ltd. | J6: =IFERROR(INDEX(TblSuppliers[Phone],MATCH(I6,TblSuppliers[Supplier],0)),"") -> +56 9 5511 2233 | K6: =IFERROR(INDEX(TblSuppliers[Delivery?],MATCH(I6,TblSuppliers[Supplier],0)),"") -> Yes
B7: =Products!B6 -> P003 | C7: =Products!C6 -> Olives 160/180, brined | D7: =Products!D6 -> Olives | E7: =Products!G6 -> Yes | F7: =Products!I6 -> Medium | G7: =Products!H6 -> Spring-Summer | H7: =IF(E7="Yes",IF(F7="Low","URGENT",IF(F7="Medium","Watch","OK")),"Low priority") -> Watch | I7: =IFERROR(INDEX(TblSupply[Supplier],MATCH(1,INDEX((TblSupply[ProductID]=B7)*(TblSupply[SupplierRole]="Primary"),0),0)),"") -> El Olivar Olives Ltd. | J7: =IFERROR(INDEX(TblSuppliers[Phone],MATCH(I7,TblSuppliers[Supplier],0)),"") -> +56 9 5511 2233 | K7: =IFERROR(INDEX(TblSuppliers[Delivery?],MATCH(I7,TblSuppliers[Supplier],0)),"") -> Yes
B8: =Products!B7 -> P004 | C8: =Products!C7 -> Olives 180/200, brined | D8: =Products!D7 -> Olives | E8: =Products!G7 -> No | F8: =Products!I7 -> Medium | G8: =Products!H7 -> Spring-Summer | H8: =IF(E8="Yes",IF(F8="Low","URGENT",IF(F8="Medium","Watch","OK")),"Low priority") -> Low priority | I8: =IFERROR(INDEX(TblSupply[Supplier],MATCH(1,INDEX((TblSupply[ProductID]=B8)*(TblSupply[SupplierRole]="Primary"),0),0)),"") -> El Olivar Olives Ltd. | J8: =IFERROR(INDEX(TblSuppliers[Phone],MATCH(I8,TblSuppliers[Supplier],0)),"") -> +56 9 5511 2233 | K8: =IFERROR(INDEX(TblSuppliers[Delivery?],MATCH(I8,TblSuppliers[Supplier],0)),"") -> Yes
B9: =Products!B8 -> P005 | C9: =Products!C8 -> Olives 200/220, brined | D9: =Products!D8 -> Olives | E9: =Products!G8 -> Yes | F9: =Products!I8 -> High | G9: =Products!H8 -> Spring-Summer | H9: =IF(E9="Yes",IF(F9="Low","URGENT",IF(F9="Medium","Watch","OK")),"Low priority") -> OK | I9: =IFERROR(INDEX(TblSupply[Supplier],MATCH(1,INDEX((TblSupply[ProductID]=B9)*(TblSupply[SupplierRole]="Primary"),0),0)),"") -> El Olivar Olives Ltd. | J9: =IFERROR(INDEX(TblSuppliers[Phone],MATCH(I9,TblSuppliers[Supplier],0)),"") -> +56 9 5511 2233 | K9: =IFERROR(INDEX(TblSuppliers[Delivery?],MATCH(I9,TblSuppliers[Supplier],0)),"") -> Yes
B10: =Products!B9 -> P006 | C10: =Products!C9 -> Olives 220/240, brined | D10: =Products!D9 -> Olives | E10: =Products!G9 -> No | F10: =Products!I9 -> High | G10: =Products!H9 -> Spring-Summer | H10: =IF(E10="Yes",IF(F10="Low","URGENT",IF(F10="Medium","Watch","OK")),"Low priority") -> Low priority | I10: =IFERROR(INDEX(TblSupply[Supplier],MATCH(1,INDEX((TblSupply[ProductID]=B10)*(TblSupply[SupplierRole]="Primary"),0),0)),"") -> El Olivar Olives Ltd. | J10: =IFERROR(INDEX(TblSuppliers[Phone],MATCH(I10,TblSuppliers[Supplier],0)),"") -> +56 9 5511 2233 | K10: =IFERROR(INDEX(TblSuppliers[Delivery?],MATCH(I10,TblSuppliers[Supplier],0)),"") -> Yes
